2018-06-02 09:27:57,253 [Thread-2:7800] [django.request:118] [exception:handle_uncaught_exception] [ERROR]- Internal Server Error: /
Traceback (most recent call last):
  File "F:\env\env_mysite\lib\site-packages\django\template\backends\django.py", line 61, in render
    return self.template.render(context)
  File "F:\env\env_mysite\lib\site-packages\django\template\base.py", line 175, in render
    return self._render(context)
  File "F:\env\env_mysite\lib\site-packages\django\template\base.py", line 167, in _render
    return self.nodelist.render(context)
  File "F:\env\env_mysite\lib\site-packages\django\template\base.py", line 943, in render
    bit = node.render_annotated(context)
  File "F:\env\env_mysite\lib\site-packages\django\template\base.py", line 910, in render_annotated
    return self.render(context)
  File "F:\env\env_mysite\lib\site-packages\django\template\loader_tags.py", line 132, in render
    compiled_parent = self.get_parent(context)
  File "F:\env\env_mysite\lib\site-packages\django\template\loader_tags.py", line 129, in get_parent
    return self.find_template(parent, context)
  File "F:\env\env_mysite\lib\site-packages\django\template\loader_tags.py", line 109, in find_template
    template_name, skip=history,
  File "F:\env\env_mysite\lib\site-packages\django\template\engine.py", line 130, in find_template
    raise TemplateDoesNotExist(name, tried=tried)
django.template.exceptions.TemplateDoesNotExist: base.html

The above exception was the direct cause of the following exception:

Traceback (most recent call last):
  File "F:\env\env_mysite\lib\site-packages\django\core\handlers\exception.py", line 35, in inner
    response = get_response(request)
  File "F:\env\env_mysite\lib\site-packages\django\core\handlers\base.py", line 128, in _get_response
    response = self.process_exception_by_middleware(e, request)
  File "F:\env\env_mysite\lib\site-packages\django\core\handlers\base.py", line 126, in _get_response
    response = wrapped_callback(request, *callback_args, **callback_kwargs)
  File "F:\django\blog_project\blog\views.py", line 12, in index
    return render(request,'index.html',locals())
  File "F:\env\env_mysite\lib\site-packages\django\shortcuts.py", line 36, in render
    content = loader.render_to_string(template_name, context, request, using=using)
  File "F:\env\env_mysite\lib\site-packages\django\template\loader.py", line 62, in render_to_string
    return template.render(context, request)
  File "F:\env\env_mysite\lib\site-packages\django\template\backends\django.py", line 63, in render
    reraise(exc, self.backend)
  File "F:\env\env_mysite\lib\site-packages\django\template\backends\django.py", line 84, in reraise
    raise new from exc
django.template.exceptions.TemplateDoesNotExist: base.html
2018-06-02 09:27:57,712 [Thread-3:11280] [django.request:93] [base:get_response] [WARNING]- Not Found: /favicon.ico
2018-06-02 09:30:04,910 [Thread-4:9560] [django.request:118] [exception:handle_uncaught_exception] [ERROR]- Internal Server Error: /
Traceback (most recent call last):
  File "F:\env\env_mysite\lib\site-packages\django\template\backends\django.py", line 61, in render
    return self.template.render(context)
  File "F:\env\env_mysite\lib\site-packages\django\template\base.py", line 175, in render
    return self._render(context)
  File "F:\env\env_mysite\lib\site-packages\django\template\base.py", line 167, in _render
    return self.nodelist.render(context)
  File "F:\env\env_mysite\lib\site-packages\django\template\base.py", line 943, in render
    bit = node.render_annotated(context)
  File "F:\env\env_mysite\lib\site-packages\django\template\base.py", line 910, in render_annotated
    return self.render(context)
  File "F:\env\env_mysite\lib\site-packages\django\template\loader_tags.py", line 132, in render
    compiled_parent = self.get_parent(context)
  File "F:\env\env_mysite\lib\site-packages\django\template\loader_tags.py", line 129, in get_parent
    return self.find_template(parent, context)
  File "F:\env\env_mysite\lib\site-packages\django\template\loader_tags.py", line 109, in find_template
    template_name, skip=history,
  File "F:\env\env_mysite\lib\site-packages\django\template\engine.py", line 130, in find_template
    raise TemplateDoesNotExist(name, tried=tried)
django.template.exceptions.TemplateDoesNotExist: base.html

The above exception was the direct cause of the following exception:

Traceback (most recent call last):
  File "F:\env\env_mysite\lib\site-packages\django\core\handlers\exception.py", line 35, in inner
    response = get_response(request)
  File "F:\env\env_mysite\lib\site-packages\django\core\handlers\base.py", line 128, in _get_response
    response = self.process_exception_by_middleware(e, request)
  File "F:\env\env_mysite\lib\site-packages\django\core\handlers\base.py", line 126, in _get_response
    response = wrapped_callback(request, *callback_args, **callback_kwargs)
  File "F:\django\blog_project\blog\views.py", line 12, in index
    return render(request,'index.html',locals())
  File "F:\env\env_mysite\lib\site-packages\django\shortcuts.py", line 36, in render
    content = loader.render_to_string(template_name, context, request, using=using)
  File "F:\env\env_mysite\lib\site-packages\django\template\loader.py", line 62, in render_to_string
    return template.render(context, request)
  File "F:\env\env_mysite\lib\site-packages\django\template\backends\django.py", line 63, in render
    reraise(exc, self.backend)
  File "F:\env\env_mysite\lib\site-packages\django\template\backends\django.py", line 84, in reraise
    raise new from exc
django.template.exceptions.TemplateDoesNotExist: base.html
2018-06-02 09:31:26,991 [Thread-11:17720] [django.request:118] [exception:handle_uncaught_exception] [ERROR]- Internal Server Error: /
Traceback (most recent call last):
  File "F:\env\env_mysite\lib\site-packages\django\template\backends\django.py", line 61, in render
    return self.template.render(context)
  File "F:\env\env_mysite\lib\site-packages\django\template\base.py", line 175, in render
    return self._render(context)
  File "F:\env\env_mysite\lib\site-packages\django\template\base.py", line 167, in _render
    return self.nodelist.render(context)
  File "F:\env\env_mysite\lib\site-packages\django\template\base.py", line 943, in render
    bit = node.render_annotated(context)
  File "F:\env\env_mysite\lib\site-packages\django\template\base.py", line 910, in render_annotated
    return self.render(context)
  File "F:\env\env_mysite\lib\site-packages\django\template\loader_tags.py", line 132, in render
    compiled_parent = self.get_parent(context)
  File "F:\env\env_mysite\lib\site-packages\django\template\loader_tags.py", line 129, in get_parent
    return self.find_template(parent, context)
  File "F:\env\env_mysite\lib\site-packages\django\template\loader_tags.py", line 109, in find_template
    template_name, skip=history,
  File "F:\env\env_mysite\lib\site-packages\django\template\engine.py", line 130, in find_template
    raise TemplateDoesNotExist(name, tried=tried)
django.template.exceptions.TemplateDoesNotExist: base.html

The above exception was the direct cause of the following exception:

Traceback (most recent call last):
  File "F:\env\env_mysite\lib\site-packages\django\core\handlers\exception.py", line 35, in inner
    response = get_response(request)
  File "F:\env\env_mysite\lib\site-packages\django\core\handlers\base.py", line 128, in _get_response
    response = self.process_exception_by_middleware(e, request)
  File "F:\env\env_mysite\lib\site-packages\django\core\handlers\base.py", line 126, in _get_response
    response = wrapped_callback(request, *callback_args, **callback_kwargs)
  File "F:\django\blog_project\blog\views.py", line 12, in index
    return render(request,'index.html',locals())
  File "F:\env\env_mysite\lib\site-packages\django\shortcuts.py", line 36, in render
    content = loader.render_to_string(template_name, context, request, using=using)
  File "F:\env\env_mysite\lib\site-packages\django\template\loader.py", line 62, in render_to_string
    return template.render(context, request)
  File "F:\env\env_mysite\lib\site-packages\django\template\backends\django.py", line 63, in render
    reraise(exc, self.backend)
  File "F:\env\env_mysite\lib\site-packages\django\template\backends\django.py", line 84, in reraise
    raise new from exc
django.template.exceptions.TemplateDoesNotExist: base.html
2018-06-02 09:31:42,606 [Thread-14:10288] [django.request:118] [exception:handle_uncaught_exception] [ERROR]- Internal Server Error: /
Traceback (most recent call last):
  File "F:\env\env_mysite\lib\site-packages\django\template\backends\django.py", line 61, in render
    return self.template.render(context)
  File "F:\env\env_mysite\lib\site-packages\django\template\base.py", line 175, in render
    return self._render(context)
  File "F:\env\env_mysite\lib\site-packages\django\template\base.py", line 167, in _render
    return self.nodelist.render(context)
  File "F:\env\env_mysite\lib\site-packages\django\template\base.py", line 943, in render
    bit = node.render_annotated(context)
  File "F:\env\env_mysite\lib\site-packages\django\template\base.py", line 910, in render_annotated
    return self.render(context)
  File "F:\env\env_mysite\lib\site-packages\django\template\loader_tags.py", line 58, in render
    result = self.nodelist.render(context)
  File "F:\env\env_mysite\lib\site-packages\django\template\base.py", line 943, in render
    bit = node.render_annotated(context)
  File "F:\env\env_mysite\lib\site-packages\django\template\base.py", line 910, in render_annotated
    return self.render(context)
  File "F:\env\env_mysite\lib\site-packages\django\template\loader_tags.py", line 182, in render
    template = context.template.engine.get_template(template_name)
  File "F:\env\env_mysite\lib\site-packages\django\template\engine.py", line 144, in get_template
    template, origin = self.find_template(template_name)
  File "F:\env\env_mysite\lib\site-packages\django\template\engine.py", line 130, in find_template
    raise TemplateDoesNotExist(name, tried=tried)
django.template.exceptions.TemplateDoesNotExist: ad.html

The above exception was the direct cause of the following exception:

Traceback (most recent call last):
  File "F:\env\env_mysite\lib\site-packages\django\core\handlers\exception.py", line 35, in inner
    response = get_response(request)
  File "F:\env\env_mysite\lib\site-packages\django\core\handlers\base.py", line 128, in _get_response
    response = self.process_exception_by_middleware(e, request)
  File "F:\env\env_mysite\lib\site-packages\django\core\handlers\base.py", line 126, in _get_response
    response = wrapped_callback(request, *callback_args, **callback_kwargs)
  File "F:\django\blog_project\blog\views.py", line 12, in index
    return render(request,'index.html',locals())
  File "F:\env\env_mysite\lib\site-packages\django\shortcuts.py", line 36, in render
    content = loader.render_to_string(template_name, context, request, using=using)
  File "F:\env\env_mysite\lib\site-packages\django\template\loader.py", line 62, in render_to_string
    return template.render(context, request)
  File "F:\env\env_mysite\lib\site-packages\django\template\backends\django.py", line 63, in render
    reraise(exc, self.backend)
  File "F:\env\env_mysite\lib\site-packages\django\template\backends\django.py", line 84, in reraise
    raise new from exc
django.template.exceptions.TemplateDoesNotExist: ad.html
2018-06-02 09:31:45,078 [Thread-15:11304] [django.request:118] [exception:handle_uncaught_exception] [ERROR]- Internal Server Error: /
Traceback (most recent call last):
  File "F:\env\env_mysite\lib\site-packages\django\template\backends\django.py", line 61, in render
    return self.template.render(context)
  File "F:\env\env_mysite\lib\site-packages\django\template\base.py", line 175, in render
    return self._render(context)
  File "F:\env\env_mysite\lib\site-packages\django\template\base.py", line 167, in _render
    return self.nodelist.render(context)
  File "F:\env\env_mysite\lib\site-packages\django\template\base.py", line 943, in render
    bit = node.render_annotated(context)
  File "F:\env\env_mysite\lib\site-packages\django\template\base.py", line 910, in render_annotated
    return self.render(context)
  File "F:\env\env_mysite\lib\site-packages\django\template\loader_tags.py", line 58, in render
    result = self.nodelist.render(context)
  File "F:\env\env_mysite\lib\site-packages\django\template\base.py", line 943, in render
    bit = node.render_annotated(context)
  File "F:\env\env_mysite\lib\site-packages\django\template\base.py", line 910, in render_annotated
    return self.render(context)
  File "F:\env\env_mysite\lib\site-packages\django\template\loader_tags.py", line 182, in render
    template = context.template.engine.get_template(template_name)
  File "F:\env\env_mysite\lib\site-packages\django\template\engine.py", line 144, in get_template
    template, origin = self.find_template(template_name)
  File "F:\env\env_mysite\lib\site-packages\django\template\engine.py", line 130, in find_template
    raise TemplateDoesNotExist(name, tried=tried)
django.template.exceptions.TemplateDoesNotExist: ad.html

The above exception was the direct cause of the following exception:

Traceback (most recent call last):
  File "F:\env\env_mysite\lib\site-packages\django\core\handlers\exception.py", line 35, in inner
    response = get_response(request)
  File "F:\env\env_mysite\lib\site-packages\django\core\handlers\base.py", line 128, in _get_response
    response = self.process_exception_by_middleware(e, request)
  File "F:\env\env_mysite\lib\site-packages\django\core\handlers\base.py", line 126, in _get_response
    response = wrapped_callback(request, *callback_args, **callback_kwargs)
  File "F:\django\blog_project\blog\views.py", line 12, in index
    return render(request,'index.html',locals())
  File "F:\env\env_mysite\lib\site-packages\django\shortcuts.py", line 36, in render
    content = loader.render_to_string(template_name, context, request, using=using)
  File "F:\env\env_mysite\lib\site-packages\django\template\loader.py", line 62, in render_to_string
    return template.render(context, request)
  File "F:\env\env_mysite\lib\site-packages\django\template\backends\django.py", line 63, in render
    reraise(exc, self.backend)
  File "F:\env\env_mysite\lib\site-packages\django\template\backends\django.py", line 84, in reraise
    raise new from exc
django.template.exceptions.TemplateDoesNotExist: ad.html
2018-06-02 09:34:01,156 [Thread-16:5412] [django.request:93] [base:get_response] [WARNING]- Not Found: /index
2018-06-02 09:34:28,023 [Thread-17:16312] [django.request:118] [exception:handle_uncaught_exception] [ERROR]- Internal Server Error: /
Traceback (most recent call last):
  File "F:\env\env_mysite\lib\site-packages\django\template\backends\django.py", line 61, in render
    return self.template.render(context)
  File "F:\env\env_mysite\lib\site-packages\django\template\base.py", line 175, in render
    return self._render(context)
  File "F:\env\env_mysite\lib\site-packages\django\template\base.py", line 167, in _render
    return self.nodelist.render(context)
  File "F:\env\env_mysite\lib\site-packages\django\template\base.py", line 943, in render
    bit = node.render_annotated(context)
  File "F:\env\env_mysite\lib\site-packages\django\template\base.py", line 910, in render_annotated
    return self.render(context)
  File "F:\env\env_mysite\lib\site-packages\django\template\loader_tags.py", line 132, in render
    compiled_parent = self.get_parent(context)
  File "F:\env\env_mysite\lib\site-packages\django\template\loader_tags.py", line 129, in get_parent
    return self.find_template(parent, context)
  File "F:\env\env_mysite\lib\site-packages\django\template\loader_tags.py", line 109, in find_template
    template_name, skip=history,
  File "F:\env\env_mysite\lib\site-packages\django\template\engine.py", line 130, in find_template
    raise TemplateDoesNotExist(name, tried=tried)
django.template.exceptions.TemplateDoesNotExist: base.html

The above exception was the direct cause of the following exception:

Traceback (most recent call last):
  File "F:\env\env_mysite\lib\site-packages\django\core\handlers\exception.py", line 35, in inner
    response = get_response(request)
  File "F:\env\env_mysite\lib\site-packages\django\core\handlers\base.py", line 128, in _get_response
    response = self.process_exception_by_middleware(e, request)
  File "F:\env\env_mysite\lib\site-packages\django\core\handlers\base.py", line 126, in _get_response
    response = wrapped_callback(request, *callback_args, **callback_kwargs)
  File "F:\django\blog_project\blog\views.py", line 12, in index
    return render(request,'index.html',locals())
  File "F:\env\env_mysite\lib\site-packages\django\shortcuts.py", line 36, in render
    content = loader.render_to_string(template_name, context, request, using=using)
  File "F:\env\env_mysite\lib\site-packages\django\template\loader.py", line 62, in render_to_string
    return template.render(context, request)
  File "F:\env\env_mysite\lib\site-packages\django\template\backends\django.py", line 63, in render
    reraise(exc, self.backend)
  File "F:\env\env_mysite\lib\site-packages\django\template\backends\django.py", line 84, in reraise
    raise new from exc
django.template.exceptions.TemplateDoesNotExist: base.html
2018-06-02 09:51:17,256 [Thread-2:13152] [django.request:118] [exception:handle_uncaught_exception] [ERROR]- Internal Server Error: /
Traceback (most recent call last):
  File "F:\env\env_mysite\lib\site-packages\django\core\handlers\exception.py", line 35, in inner
    response = get_response(request)
  File "F:\env\env_mysite\lib\site-packages\django\core\handlers\base.py", line 128, in _get_response
    response = self.process_exception_by_middleware(e, request)
  File "F:\env\env_mysite\lib\site-packages\django\core\handlers\base.py", line 126, in _get_response
    response = wrapped_callback(request, *callback_args, **callback_kwargs)
  File "F:\django\blog_project\blog\views.py", line 18, in index
    return render(request,'index.html',locals())
  File "F:\env\env_mysite\lib\site-packages\django\shortcuts.py", line 36, in render
    content = loader.render_to_string(template_name, context, request, using=using)
  File "F:\env\env_mysite\lib\site-packages\django\template\loader.py", line 62, in render_to_string
    return template.render(context, request)
  File "F:\env\env_mysite\lib\site-packages\django\template\backends\django.py", line 61, in render
    return self.template.render(context)
  File "F:\env\env_mysite\lib\site-packages\django\template\base.py", line 173, in render
    with context.bind_template(self):
  File "e:\python3.6\Lib\contextlib.py", line 81, in __enter__
    return next(self.gen)
  File "F:\env\env_mysite\lib\site-packages\django\template\context.py", line 250, in bind_template
    updates.update(processor(self.request))
TypeError: global_setting() takes 0 positional arguments but 1 was given
